Traceback (most recent call last):
  File "/home/runner/work/artificial-intelligence/artificial-intelligence/.venv/lib/python3.10/site-packages/jupyter_cache/executors/utils.py", line 58, in single_nb_execution
    executenb(
  File "/home/runner/work/artificial-intelligence/artificial-intelligence/.venv/lib/python3.10/site-packages/nbclient/client.py", line 1204, in execute
    return NotebookClient(nb=nb, resources=resources, km=km, **kwargs).execute()
  File "/home/runner/work/artificial-intelligence/artificial-intelligence/.venv/lib/python3.10/site-packages/nbclient/util.py", line 84, in wrapped
    return just_run(coro(*args, **kwargs))
  File "/home/runner/work/artificial-intelligence/artificial-intelligence/.venv/lib/python3.10/site-packages/nbclient/util.py", line 62, in just_run
    return loop.run_until_complete(coro)
  File "/opt/hostedtoolcache/Python/3.10.10/x64/lib/python3.10/asyncio/base_events.py", line 649, in run_until_complete
    return future.result()
  File "/home/runner/work/artificial-intelligence/artificial-intelligence/.venv/lib/python3.10/site-packages/nbclient/client.py", line 663, in async_execute
    await self.async_execute_cell(
  File "/home/runner/work/artificial-intelligence/artificial-intelligence/.venv/lib/python3.10/site-packages/nbclient/client.py", line 965, in async_execute_cell
    await self._check_raise_for_error(cell, cell_index, exec_reply)
  File "/home/runner/work/artificial-intelligence/artificial-intelligence/.venv/lib/python3.10/site-packages/nbclient/client.py", line 862, in _check_raise_for_error
    raise CellExecutionError.from_cell_and_msg(cell, exec_reply_content)
nbclient.exceptions.CellExecutionError: An error occurred while executing the following cell:
------------------
# Some basic setup:
# Setup detectron2 logger
import detectron2
from detectron2.utils.logger import setup_logger
setup_logger()

# import some common libraries
import numpy as np
import os, json, cv2, random
from google.colab.patches import cv2_imshow

# import some common detectron2 utilities
from detectron2 import model_zoo
from detectron2.engine import DefaultPredictor
from detectron2.config import get_cfg
from detectron2.utils.visualizer import Visualizer
from detectron2.data import MetadataCatalog, DatasetCatalog
------------------

[0;31m---------------------------------------------------------------------------[0m
[0;31mModuleNotFoundError[0m                       Traceback (most recent call last)
Cell [0;32mIn[4], line 9[0m
[1;32m      7[0m [38;5;66;03m# import some common libraries[39;00m
[1;32m      8[0m [38;5;28;01mimport[39;00m [38;5;21;01mnumpy[39;00m [38;5;28;01mas[39;00m [38;5;21;01mnp[39;00m
[0;32m----> 9[0m [38;5;28;01mimport[39;00m [38;5;21;01mos[39;00m[38;5;241m,[39m [38;5;21;01mjson[39;00m[38;5;241m,[39m [38;5;21;01mcv2[39;00m[38;5;241m,[39m [38;5;21;01mrandom[39;00m
[1;32m     10[0m [38;5;28;01mfrom[39;00m [38;5;21;01mgoogle[39;00m[38;5;21;01m.[39;00m[38;5;21;01mcolab[39;00m[38;5;21;01m.[39;00m[38;5;21;01mpatches[39;00m [38;5;28;01mimport[39;00m cv2_imshow
[1;32m     12[0m [38;5;66;03m# import some common detectron2 utilities[39;00m

[0;31mModuleNotFoundError[0m: No module named 'cv2'
ModuleNotFoundError: No module named 'cv2'

