Traceback (most recent call last):
  File "/home/runner/work/artificial-intelligence/artificial-intelligence/.venv/lib/python3.10/site-packages/jupyter_cache/executors/utils.py", line 58, in single_nb_execution
    executenb(
  File "/home/runner/work/artificial-intelligence/artificial-intelligence/.venv/lib/python3.10/site-packages/nbclient/client.py", line 1204, in execute
    return NotebookClient(nb=nb, resources=resources, km=km, **kwargs).execute()
  File "/home/runner/work/artificial-intelligence/artificial-intelligence/.venv/lib/python3.10/site-packages/nbclient/util.py", line 84, in wrapped
    return just_run(coro(*args, **kwargs))
  File "/home/runner/work/artificial-intelligence/artificial-intelligence/.venv/lib/python3.10/site-packages/nbclient/util.py", line 62, in just_run
    return loop.run_until_complete(coro)
  File "/opt/hostedtoolcache/Python/3.10.10/x64/lib/python3.10/asyncio/base_events.py", line 649, in run_until_complete
    return future.result()
  File "/home/runner/work/artificial-intelligence/artificial-intelligence/.venv/lib/python3.10/site-packages/nbclient/client.py", line 663, in async_execute
    await self.async_execute_cell(
  File "/home/runner/work/artificial-intelligence/artificial-intelligence/.venv/lib/python3.10/site-packages/nbclient/client.py", line 965, in async_execute_cell
    await self._check_raise_for_error(cell, cell_index, exec_reply)
  File "/home/runner/work/artificial-intelligence/artificial-intelligence/.venv/lib/python3.10/site-packages/nbclient/client.py", line 862, in _check_raise_for_error
    raise CellExecutionError.from_cell_and_msg(cell, exec_reply_content)
nbclient.exceptions.CellExecutionError: An error occurred while executing the following cell:
------------------
import os
import sys
import numpy as np
import tensorflow as tf
import matplotlib
import matplotlib.pyplot as plt
import keras

# Root directory of the project
ROOT_DIR = os.path.abspath("../../")

# Import Mask RCNN
sys.path.append(ROOT_DIR)  # To find local version of the library
from mrcnn import utils
import mrcnn.model as modellib
from mrcnn import visualize
from mrcnn.model import log

%matplotlib inline 

# Directory to save logs and trained model
MODEL_DIR = os.path.join(ROOT_DIR, "logs")

# Local path to trained weights file
COCO_MODEL_PATH = os.path.join(ROOT_DIR, "mask_rcnn_coco.h5")
# Download COCO trained weights from Releases if needed
if not os.path.exists(COCO_MODEL_PATH):
    utils.download_trained_weights(COCO_MODEL_PATH)

# Path to Shapes trained weights
SHAPES_MODEL_PATH = os.path.join(ROOT_DIR, "mask_rcnn_shapes.h5")
------------------

[0;31m---------------------------------------------------------------------------[0m
[0;31mModuleNotFoundError[0m                       Traceback (most recent call last)
Cell [0;32mIn[1], line 14[0m
[1;32m     12[0m [38;5;66;03m# Import Mask RCNN[39;00m
[1;32m     13[0m sys[38;5;241m.[39mpath[38;5;241m.[39mappend(ROOT_DIR)  [38;5;66;03m# To find local version of the library[39;00m
[0;32m---> 14[0m [38;5;28;01mfrom[39;00m [38;5;21;01mmrcnn[39;00m [38;5;28;01mimport[39;00m utils
[1;32m     15[0m [38;5;28;01mimport[39;00m [38;5;21;01mmrcnn[39;00m[38;5;21;01m.[39;00m[38;5;21;01mmodel[39;00m [38;5;28;01mas[39;00m [38;5;21;01mmodellib[39;00m
[1;32m     16[0m [38;5;28;01mfrom[39;00m [38;5;21;01mmrcnn[39;00m [38;5;28;01mimport[39;00m visualize

[0;31mModuleNotFoundError[0m: No module named 'mrcnn'
ModuleNotFoundError: No module named 'mrcnn'

